<?xml version="1.0"?>
<robot name="oneArm">
	<link name="base_link">
		<visual>
			<geometry>
				<cylinder length="0.049" radius="0.1" />
			</geometry>
			<origin rpy="0 0 0" xyz="0 0 0.0245" />
			<material name="yellow">
				<color rgba="1 1 0 1" />
			</material>
		</visual>
	</link>

	<joint name="joint1" type="revolute">
		<parent link="base_link" />
		<child link="link1" />
		<origin xyz="0 0 0.049" />
		<axis xyz="0 0 1" />
	</joint>

	<link name="link1">
		<visual>
			<geometry>
				<cylinder length="0.02" radius="0.033" />
			</geometry>
			<origin rpy="0 0 0" xyz="0 0 0.01" />
			<material name="green">
				<color rgba="0 1 0 1" />
			</material>
		</visual>
	</link>

	<joint name="joint2" type="revolute">
		<parent link="link1" />
		<child link="link2" />
		<origin xyz="0 0 0.02" />
		<axis xyz="0 -1 0" />
	</joint>

	<link name="link2">
		<visual>
			<geometry>
				<cylinder length="0.12" radius="0.03" />
			</geometry>
			<origin rpy="0 0 0" xyz="0 0 0.06" />
			<material name="blue">
				<color rgba="0 0 1 1" />
			</material>
		</visual>
	</link>

	<joint name="joint3" type="revolute">
		<parent link="link2" />
		<child link="link3" />
		<origin xyz="0 0 0.12" />
		<axis xyz="0 -1 0" />
	</joint>

	<link name="link3">
		<visual>
			<geometry>
				<cylinder length="0.127" radius="0.03" />
			</geometry>
			<origin rpy="0 0 0" xyz="0 0 0.0635" />
			<material name="red">
				<color rgba="1 0 0 1" />
			</material>
		</visual>
	</link>

	<joint name="joint4" type="revolute">
		<parent link="link3" />
		<child link="link4" />
		<origin xyz="0 0 0.127" />
		<axis xyz="0 -1 0" />
	</joint>

	<link name="link4">
		<visual>
			<geometry>
				<cylinder length="0.031" radius="0.03" />
			</geometry>
			<origin rpy="0 0 0" xyz="0 0 0.0195" />
			<material name="black">
				<color rgba="0 0 0 1" />
			</material>
		</visual>
	</link>

	<joint name="joint5" type="revolute">
		<parent link="link4" />
		<child link="link5" />
		<origin xyz="0 0 0.031" />
		<axis xyz="0 0 1" />
	</joint>

	<link name="link5">
		<visual>
			<geometry>
				<cylinder length="0.008" radius="0.025" />
			</geometry>
			<origin rpy="0 0 0" xyz="0 0 0.0125" />
			<material name="black">
				<color rgba="0 0 0 1" />
			</material>
		</visual>
	</link>

</robot>
